<robot name="self_balance_bot" version="1.0">
  <joint name="wheel_left_link_joint" type="continuous">
    <limit effort="50.00000" velocity="157.07001"/>
    <origin rpy="0.00000 1.57080 -0.00000" xyz="0.28374 -0.00000 -0.23648"/>
    <parent link="base_link"/>
    <child link="wheel_left_link"/>
    <axis xyz="0.00000 0.00000 1.00000"/>
  </joint>
  <joint name="wheel_right_link_joint" type="continuous">
    <limit effort="50.00000" velocity="157.07001"/>
    <origin rpy="0.00000 1.57080 -0.00000" xyz="-0.28374 0.00000 -0.23648"/>
    <parent link="base_link"/>
    <child link="wheel_right_link"/>
    <axis xyz="0.00000 0.00000 1.00000"/>
  </joint>
  <link name="base_link">
    <collision name="body_collision">
      <origin rpy="0.00000 0.00000 -1.57080" xyz="0.00000 0.00000 0.00000"/>
      <geometry>
        <box size="0.30856 0.40852 0.59953"/>
      </geometry>
    </collision>
    <inertial>
      <inertia ixx="0.04386" ixy="-0.00000" ixz="0.00000" iyy="0.03789" iyz="0.00000" izz="0.02184"/>
      <origin rpy="0.00000 0.00000 0.00000" xyz="0.00000 0.00000 0.00000"/>
      <mass value="1.00000"/>
    </inertial>
    <visual name="body">
      <material name="Body"/>
      <origin rpy="0.00000 0.00000 -1.57080" xyz="0.00000 0.00000 0.00000"/>
      <geometry>
        <box size="0.30000 0.40000 0.60000"/>
      </geometry>
    </visual>
  </link>
  <link name="wheel_left_link">
    <collision name="wheel_left_collision">
      <origin rpy="0.00000 0.00000 -0.00000" xyz="0.00000 0.00000 -0.00000"/>
      <geometry>
        <cylinder radius="0.20074" length="0.15751"/>
      </geometry>
    </collision>
    <inertial>
      <inertia ixx="0.00304" ixy="0.00000" ixz="-0.00000" iyy="0.00504" iyz="-0.00000" izz="0.00304"/>
      <origin rpy="0.00000 0.00000 0.00000" xyz="0.00000 0.00000 -0.00000"/>
      <mass value="0.25000"/>
    </inertial>
    <visual name="wheel_left">
      <material name="Wheel"/>
      <origin rpy="0.00000 -0.00000 0.00000" xyz="0.00000 0.00000 -0.00000"/>
      <geometry>
        <cylinder radius="0.20006" length="0.14744"/>
      </geometry>
    </visual>
  </link>
  <link name="wheel_right_link">
    <collision name="wheel_right_collision">
      <origin rpy="0.00000 -0.00000 0.00000" xyz="0.00000 -0.00000 -0.00000"/>
      <geometry>
        <cylinder radius="0.20053" length="0.15093"/>
      </geometry>
    </collision>
    <inertial>
      <inertia ixx="0.00299" ixy="0.00000" ixz="-0.00000" iyy="0.00503" iyz="-0.00000" izz="0.00299"/>
      <origin rpy="0.00000 0.00000 0.00000" xyz="0.00000 -0.00000 0.00000"/>
      <mass value="0.25000"/>
    </inertial>
    <visual name="wheel_right">
      <material name="Wheel"/>
      <origin rpy="0.00000 -0.00000 0.00000" xyz="0.00000 0.00000 0.00000"/>
      <geometry>
        <cylinder radius="0.20006" length="0.14744"/>
      </geometry>
    </visual>
  </link>
  <material name="Body">
    <color rgba="0.17255 0.51373 0.80000 1.00000"/>
  </material>
  <material name="Wheel">
    <color rgba="0.00000 0.00000 0.00000 1.00000"/>
  </material>
</robot>